Workbook

Sheet INPUTS
A1: インプット（変数設定）
A2: 物件価格 | B2: 100000000 | C2: 円 | E2: ※割合・率は 0～1 の小数で入力（例：5% → 0.05）。単位はC列参照。
A3: 建物価格割合 | B3: 0.5
A4: 土地価格割合 | B4: =1-B3 -> 0.5
A5: 建物法定耐用年数 | B5: 7 | C5: 年 | E5: 鉄骨造34年の20%
A6: 頭金割合 | B6: 0.05
A7: 借入割合 | B7: 0.95
A8: 利回り（想定） | B8: 0.09
A9: 家賃下落率 | B9: 0.01
A10: 空室率（％） | B10: 0.05
A11: 管理費（％/家賃） | B11: 0.15
A12: その他経費（％/家賃） | B12: 0.05
A13: 役員報酬（円） | B13: 0.03
A14: 借入期間（年） | B14: 35 | C14: 年
A15: 金利（％） | B15: 0.033
A16: 法人税等実効税率 | B16: 0.23
A18: 【仕様メモ】
A19: ・借入：元金均等（借入額/借入期間）。利息=期首残×金利。
A20: ・家賃：物件価格×利回り×(1-家賃下落率)^(年-1)×(1-空室率)。
A21: ・管理費/その他：家賃に対する％（B列は小数入力、C列に％表記）。
A22: ・減価償却：建物（価格×建物割合）を定額で耐用年数按分。
A23: ・役員報酬：固定額。
A24: ・税金：MAX(税引前利益,0)×実効税率。
A25: ・FCF：税引後利益＋減価償却?元本返済。

Sheet OUTPUT
A1: 不動産投資シミュレーション（OUTPUT）
A2: 上：簡易PL／中：簡易CF／下：簡易BS（横=年次 1～20年）
B3: 項目＼年 | C3: 1年目 | D3: 2年目 | E3: 3年目 | F3: 4年目 | G3: 5年目 | H3: 6年目 | I3: 7年目 | J3: 8年目 | K3: 9年目 | L3: 10年目 | M3: 11年目 | N3: 12年目 | O3: 13年目 | P3: 14年目 | Q3: 15年目 | R3: 16年目 | S3: 17年目 | T3: 18年目 | U3: 19年目 | V3: 20年目
B4: 家賃収入 | C4: =INPUTS!$B$2*INPUTS!$B$8*(1-INPUTS!$B$9)^0*(1-INPUTS!$B$10) -> 8550000 | D4: =INPUTS!$B$2*INPUTS!$B$8*(1-INPUTS!$B$9)^1*(1-INPUTS!$B$10) -> 8464500 | E4: =INPUTS!$B$2*INPUTS!$B$8*(1-INPUTS!$B$9)^2*(1-INPUTS!$B$10) -> 8379855 | F4: =INPUTS!$B$2*INPUTS!$B$8*(1-INPUTS!$B$9)^3*(1-INPUTS!$B$10) -> 8296056.4 | G4: =INPUTS!$B$2*INPUTS!$B$8*(1-INPUTS!$B$9)^4*(1-INPUTS!$B$10) -> 8213095.9 | H4: =INPUTS!$B$2*INPUTS!$B$8*(1-INPUTS!$B$9)^5*(1-INPUTS!$B$10) -> 8130964.9 | I4: =INPUTS!$B$2*INPUTS!$B$8*(1-INPUTS!$B$9)^6*(1-INPUTS!$B$10) -> 8049655.3 | J4: =INPUTS!$B$2*INPUTS!$B$8*(1-INPUTS!$B$9)^7*(1-INPUTS!$B$10) -> 7969158.7 | K4: =INPUTS!$B$2*INPUTS!$B$8*(1-INPUTS!$B$9)^8*(1-INPUTS!$B$10) -> 7889467.1 | L4: =INPUTS!$B$2*INPUTS!$B$8*(1-INPUTS!$B$9)^9*(1-INPUTS!$B$10) -> 7810572.5 | M4: =INPUTS!$B$2*INPUTS!$B$8*(1-INPUTS!$B$9)^10*(1-INPUTS!$B$10) -> 7732466.7 | N4: =INPUTS!$B$2*INPUTS!$B$8*(1-INPUTS!$B$9)^11*(1-INPUTS!$B$10) -> 7655142.1 | O4: =INPUTS!$B$2*INPUTS!$B$8*(1-INPUTS!$B$9)^12*(1-INPUTS!$B$10) -> 7578590.7 | P4: =INPUTS!$B$2*INPUTS!$B$8*(1-INPUTS!$B$9)^13*(1-INPUTS!$B$10) -> 7502804.7 | Q4: =INPUTS!$B$2*INPUTS!$B$8*(1-INPUTS!$B$9)^14*(1-INPUTS!$B$10) -> 7427776.7 | R4: =INPUTS!$B$2*INPUTS!$B$8*(1-INPUTS!$B$9)^15*(1-INPUTS!$B$10) -> 7353498.9 | S4: =INPUTS!$B$2*INPUTS!$B$8*(1-INPUTS!$B$9)^16*(1-INPUTS!$B$10) -> 7279963.9 | T4: =INPUTS!$B$2*INPUTS!$B$8*(1-INPUTS!$B$9)^17*(1-INPUTS!$B$10) -> 7207164.3 | U4: =INPUTS!$B$2*INPUTS!$B$8*(1-INPUTS!$B$9)^18*(1-INPUTS!$B$10) -> 7135092.7 | V4: =INPUTS!$B$2*INPUTS!$B$8*(1-INPUTS!$B$9)^19*(1-INPUTS!$B$10) -> 7063741.7
B5: 管理費 | C5: =C4*INPUTS!$B$11 -> 1282500 | D5: =D4*INPUTS!$B$11 -> 1269675 | E5: =E4*INPUTS!$B$11 -> 1256978.2 | F5: =F4*INPUTS!$B$11 -> 1244408.5 | G5: =G4*INPUTS!$B$11 -> 1231964.4 | H5: =H4*INPUTS!$B$11 -> 1219644.7 | I5: =I4*INPUTS!$B$11 -> 1207448.3 | J5: =J4*INPUTS!$B$11 -> 1195373.8 | ... V5: =V4*INPUTS!$B$11 -> 1059561.3
B6: その他経費 | C6: =C4*INPUTS!$B$12 -> 427500 | D6: =D4*INPUTS!$B$12 -> 423225 | E6: =E4*INPUTS!$B$12 -> 418992.75 | F6: =F4*INPUTS!$B$12 -> 414802.82 | G6: =G4*INPUTS!$B$12 -> 410654.79 | H6: =H4*INPUTS!$B$12 -> 406548.25 | I6: =I4*INPUTS!$B$12 -> 402482.76 | J6: =J4*INPUTS!$B$12 -> 398457.94 | ... V6: =V4*INPUTS!$B$12 -> 353187.09
B7: 役員報酬 | C7: =C4*INPUTS!$B$13 -> 256500 | D7: =D4*INPUTS!$B$13 -> 253935 | E7: =E4*INPUTS!$B$13 -> 251395.65 | F7: =F4*INPUTS!$B$13 -> 248881.69 | G7: =G4*INPUTS!$B$13 -> 246392.88 | H7: =H4*INPUTS!$B$13 -> 243928.95 | I7: =I4*INPUTS!$B$13 -> 241489.66 | J7: =J4*INPUTS!$B$13 -> 239074.76 | ... V7: =V4*INPUTS!$B$13 -> 211912.25
B8: 減価償却費 | C8: =INPUTS!$B$2*INPUTS!$B$3/INPUTS!$B$5 -> 7142857.1 | D8: =INPUTS!$B$2*INPUTS!$B$3/INPUTS!$B$5 -> 7142857.1 | E8: =INPUTS!$B$2*INPUTS!$B$3/INPUTS!$B$5 -> 7142857.1 | F8: =INPUTS!$B$2*INPUTS!$B$3/INPUTS!$B$5 -> 7142857.1 | G8: =INPUTS!$B$2*INPUTS!$B$3/INPUTS!$B$5 -> 7142857.1 | H8: =INPUTS!$B$2*INPUTS!$B$3/INPUTS!$B$5 -> 7142857.1 | I8: =INPUTS!$B$2*INPUTS!$B$3/INPUTS!$B$5 -> 7142857.1
B9: 支払利息 | C9: =C21*INPUTS!$B$15 -> 3135000 | D9: =D21*INPUTS!$B$15 -> 3045428.6 | E9: =E21*INPUTS!$B$15 -> 2955857.1 | F9: =F21*INPUTS!$B$15 -> 2866285.7 | G9: =G21*INPUTS!$B$15 -> 2776714.3 | H9: =H21*INPUTS!$B$15 -> 2687142.9 | I9: =I21*INPUTS!$B$15 -> 2597571.4 | J9: =J21*INPUTS!$B$15 -> 2508000 | ... V9: =V21*INPUTS!$B$15 -> 1433142.9
B10: 税引前利益 | C10: =C4-C5-C6-C7-C8-C9 -> -3694357.1 | D10: =D4-D5-D6-D7-D8-D9 -> -3670620.7 | E10: =E4-E5-E6-E7-E8-E9 -> -3646225.9 | F10: =F4-F5-F6-F7-F8-F9 -> -3621179.4 | G10: =G4-G5-G6-G7-G8-G9 -> -3595487.6 | H10: =H4-H5-H6-H7-H8-H9 -> -3569157 | I10: =I4-I5-I6-I7-I8-I9 -> -3542194 | J10: =J4-J5-J6-J7-J8-J9 -> 3628252.2 | ... V10: =V4-V5-V6-V7-V8-V9 -> 4005938.3
B11: 法人税等 | C11: =MAX(C10,0)*INPUTS!$B$16 -> 0 | D11: =MAX(D10,0)*INPUTS!$B$16 -> 0 | E11: =MAX(E10,0)*INPUTS!$B$16 -> 0 | F11: =MAX(F10,0)*INPUTS!$B$16 -> 0 | G11: =MAX(G10,0)*INPUTS!$B$16 -> 0 | H11: =MAX(H10,0)*INPUTS!$B$16 -> 0 | I11: =MAX(I10,0)*INPUTS!$B$16 -> 0 | J11: =MAX(J10,0)*INPUTS!$B$16 -> 834498.01 | ... V11: =MAX(V10,0)*INPUTS!$B$16 -> 921365.8
B12: 税引後利益 | C12: =C10-C11 -> -3694357.1 | D12: =D10-D11 -> -3670620.7 | E12: =E10-E11 -> -3646225.9 | F12: =F10-F11 -> -3621179.4 | G12: =G10-G11 -> -3595487.6 | H12: =H10-H11 -> -3569157 | I12: =I10-I11 -> -3542194 | J12: =J10-J11 -> 2793754.2 | ... V12: =V10-V11 -> 3084572.5
B14: 簡易CF
B15: 税引後利益 | C15: =C12 -> -3694357.1 | D15: =D12 -> -3670620.7 | E15: =E12 -> -3646225.9 | F15: =F12 -> -3621179.4 | G15: =G12 -> -3595487.6 | H15: =H12 -> -3569157 | I15: =I12 -> -3542194 | J15: =J12 -> 2793754.2 | ... V15: =V12 -> 3084572.5
B16: 減価償却費（非資金） | C16: =C8 -> 7142857.1 | D16: =D8 -> 7142857.1 | E16: =E8 -> 7142857.1 | F16: =F8 -> 7142857.1 | G16: =G8 -> 7142857.1 | H16: =H8 -> 7142857.1 | I16: =I8 -> 7142857.1 | J16: =J8 -> 0 | ... V16: =V8 -> 0
B17: 元本返済（資金流出） | C17: =INPUTS!$B$2*INPUTS!$B$7/INPUTS!$B$14 -> 2714285.7 | D17: =INPUTS!$B$2*INPUTS!$B$7/INPUTS!$B$14 -> 2714285.7 | E17: =INPUTS!$B$2*INPUTS!$B$7/INPUTS!$B$14 -> 2714285.7 | F17: =INPUTS!$B$2*INPUTS!$B$7/INPUTS!$B$14 -> 2714285.7 | G17: =INPUTS!$B$2*INPUTS!$B$7/INPUTS!$B$14 -> 2714285.7 | H17: =INPUTS!$B$2*INPUTS!$B$7/INPUTS!$B$14 -> 2714285.7 | I17: =INPUTS!$B$2*INPUTS!$B$7/INPUTS!$B$14 -> 2714285.7 | J17: =INPUTS!$B$2*INPUTS!$B$7/INPUTS!$B$14 -> 2714285.7 | ... V17: =INPUTS!$B$2*INPUTS!$B$7/INPUTS!$B$14 -> 2714285.7
B18: FCF | C18: =C15+C16-C17 -> 734214.29 | D18: =D15+D16-D17 -> 757950.71 | E18: =E15+E16-E17 -> 782345.49 | F18: =F15+F16-F17 -> 807392.04 | G18: =G15+G16-G17 -> 833083.83 | H18: =H15+H16-H17 -> 859414.42 | I18: =I15+I16-I17 -> 886377.42 | J18: =J15+J16-J17 -> 79468.494 | ... V18: =V15+V16-V17 -> 370286.76
B20: 簡易BS
B21: 期首借入金残高 | C21: =INPUTS!$B$2*INPUTS!$B$7 -> 95000000 | D21: =OFFSET(D21,1,-1) -> 92285714 | E21: =OFFSET(E21,1,-1) -> 89571429 | F21: =OFFSET(F21,1,-1) -> 86857143 | G21: =OFFSET(G21,1,-1) -> 84142857 | H21: =OFFSET(H21,1,-1) -> 81428571 | I21: =OFFSET(I21,1,-1) -> 78714286 | J21: =OFFSET(J21,1,-1) -> 76000000 | K21: =OFFSET(K21,1,-1) -> 73285714 | ... V21: =OFFSET(V21,1,-1) -> 43428571
B22: 期末借入金残高 | C22: =C21-C17 -> 92285714 | D22: =D21-D17 -> 89571429 | E22: =E21-E17 -> 86857143 | F22: =F21-F17 -> 84142857 | G22: =G21-G17 -> 81428571 | H22: =H21-H17 -> 78714286 | I22: =I21-I17 -> 76000000 | J22: =J21-J17 -> 73285714 | ... V22: =V21-V17 -> 40714286

Sheet 返済シュミレーション (3)
C2: 借入金額 | D2: 5000 | E2: 万円 | I2: 借入金額 | J2: 5000 | K2: 万円
C3: 金利 | D3: 0.043 | I3: 金利 | J3: 0.022
C4: 返済期間 | D4: 25 | E4: 年 | I4: 返済期間 | J4: 25 | K4: 年
C5: 毎月返済額 | D5: =INT(PMT(D3/12,D4*12,-D2*10000)) -> 272270 | E5: 円 | I5: 毎月返済額 | J5: =INT(PMT(J3/12,J4*12,-J2*10000)) -> 216829 | K5: 円
C6: 年間返済額 | D6: =D5*12 -> 3267240 | I6: 年間返済額 | J6: =J5*12 -> 2601948
C8: 毎月返済額 | D8: 利息 | E8: 元金 | F8: ローン残高 | I8: 毎月返済額 | J8: 利息 | K8: 元金 | L8: ローン残高
B9: 1 | C9: =D5 -> 272270 | D9: =INT(D2*10000*D3/12) -> 179166 | E9: =C9-D9 -> 93104 | F9: =D2*10000-E9 -> 49906896 | H9: 1 | I9: =J5 -> 216829 | J9: =INT(J2*10000*J3/12) -> 91666 | K9: =I9-J9 -> 125163 | L9: =J2*10000-K9 -> 49874837
B10: =B9+1 -> 2 | C10: =C9 -> 272270 | D10: =INT(F9*$D$3/12) -> 178833 | E10: =C10-D10 -> 93437 | F10: =F9-E10 -> 49813459 | H10: =H9+1 -> 2 | I10: =I9 -> 216829 | J10: =INT(L9*$J$3/12) -> 91437 | K10: =I10-J10 -> 125392 | L10: =L9-K10 -> 49749445
B11: =B10+1 -> 3 | C11: =C10 -> 272270 | D11: =INT(F10*$D$3/12) -> 178498 | E11: =C11-D11 -> 93772 | F11: =F10-E11 -> 49719687 | H11: =H10+1 -> 3 | I11: =I10 -> 216829 | J11: =INT(L10*$J$3/12) -> 91207 | K11: =I11-J11 -> 125622 | L11: =L10-K11 -> 49623823
B12: =B11+1 -> 4 | C12: =C11 -> 272270 | D12: =INT(F11*$D$3/12) -> 178162 | E12: =C12-D12 -> 94108 | F12: =F11-E12 -> 49625579 | H12: =H11+1 -> 4 | I12: =I11 -> 216829 | J12: =INT(L11*$J$3/12) -> 90977 | K12: =I12-J12 -> 125852 | L12: =L11-K12 -> 49497971
B13: =B12+1 -> 5 | C13: =C12 -> 272270 | D13: =INT(F12*$D$3/12) -> 177824 | E13: =C13-D13 -> 94446 | F13: =F12-E13 -> 49531133 | H13: =H12+1 -> 5 | I13: =I12 -> 216829 | J13: =INT(L12*$J$3/12) -> 90746 | K13: =I13-J13 -> 126083 | L13: =L12-K13 -> 49371888
B14: =B13+1 -> 6 | C14: =C13 -> 272270 | D14: =INT(F13*$D$3/12) -> 177486 | E14: =C14-D14 -> 94784 | F14: =F13-E14 -> 49436349 | H14: =H13+1 -> 6 | I14: =I13 -> 216829 | J14: =INT(L13*$J$3/12) -> 90515 | K14: =I14-J14 -> 126314 | L14: =L13-K14 -> 49245574
B15: =B14+1 -> 7 | C15: =C14 -> 272270 | D15: =INT(F14*$D$3/12) -> 177146 | E15: =C15-D15 -> 95124 | F15: =F14-E15 -> 49341225 | H15: =H14+1 -> 7 | I15: =I14 -> 216829 | J15: =INT(L14*$J$3/12) -> 90283 | K15: =I15-J15 -> 126546 | L15: =L14-K15 -> 49119028
B16: =B15+1 -> 8 | C16: =C15 -> 272270 | D16: =INT(F15*$D$3/12) -> 176806 | E16: =C16-D16 -> 95464 | F16: =F15-E16 -> 49245761 | H16: =H15+1 -> 8 | I16: =I15 -> 216829 | J16: =INT(L15*$J$3/12) -> 90051 | K16: =I16-J16 -> 126778 | L16: =L15-K16 -> 48992250
B17: =B16+1 -> 9 | C17: =C16 -> 272270 | D17: =INT(F16*$D$3/12) -> 176463 | E17: =C17-D17 -> 95807 | F17: =F16-E17 -> 49149954 | H17: =H16+1 -> 9 | I17: =I16 -> 216829 | J17: =INT(L16*$J$3/12) -> 89819 | K17: =I17-J17 -> 127010 | L17: =L16-K17 -> 48865240
B18: =B17+1 -> 10 | C18: =C17 -> 272270 | D18: =INT(F17*$D$3/12) -> 176120 | E18: =C18-D18 -> 96150 | F18: =F17-E18 -> 49053804 | H18: =H17+1 -> 10 | I18: =I17 -> 216829 | J18: =INT(L17*$J$3/12) -> 89586 | K18: =I18-J18 -> 127243 | L18: =L17-K18 -> 48737997
B19: =B18+1 -> 11 | C19: =C18 -> 272270 | D19: =INT(F18*$D$3/12) -> 175776 | E19: =C19-D19 -> 96494 | F19: =F18-E19 -> 48957310 | H19: =H18+1 -> 11 | I19: =I18 -> 216829 | J19: =INT(L18*$J$3/12) -> 89352 | K19: =I19-J19 -> 127477 | L19: =L18-K19 -> 48610520
B20: =B19+1 -> 12 | C20: =C19 -> 272270 | D20: =INT(F19*$D$3/12) -> 175430 | E20: =C20-D20 -> 96840 | F20: =F19-E20 -> 48860470 | H20: =H19+1 -> 12 | I20: =I19 -> 216829 | J20: =INT(L19*$J$3/12) -> 89119 | K20: =I20-J20 -> 127710 | L20: =L19-K20 -> 48482810
A21: ２年 | B21: =B20+1 -> 13 | C21: =C20 -> 272270 | D21: =INT(F20*$D$3/12) -> 175083 | E21: =C21-D21 -> 97187 | F21: =F20-E21 -> 48763283 | H21: =H20+1 -> 13 | I21: =I20 -> 216829 | J21: =INT(L20*$J$3/12) -> 88885 | K21: =I21-J21 -> 127944 | L21: =L20-K21 -> 48354866
B22: =B21+1 -> 14 | C22: =C21 -> 272270 | D22: =INT(F21*$D$3/12) -> 174735 | E22: =C22-D22 -> 97535 | F22: =F21-E22 -> 48665748 | H22: =H21+1 -> 14 | I22: =I21 -> 216829 | J22: =INT(L21*$J$3/12) -> 88650 | K22: =I22-J22 -> 128179 | L22: =L21-K22 -> 48226687
B23: =B22+1 -> 15 | C23: =C22 -> 272270 | D23: =INT(F22*$D$3/12) -> 174385 | E23: =C23-D23 -> 97885 | F23: =F22-E23 -> 48567863 | H23: =H22+1 -> 15 | I23: =I22 -> 216829 | J23: =INT(L22*$J$3/12) -> 88415 | K23: =I23-J23 -> 128414 | L23: =L22-K23 -> 48098273
B24: =B23+1 -> 16 | C24: =C23 -> 272270 | D24: =INT(F23*$D$3/12) -> 174034 | E24: =C24-D24 -> 98236 | F24: =F23-E24 -> 48469627 | H24: =H23+1 -> 16 | I24: =I23 -> 216829 | J24: =INT(L23*$J$3/12) -> 88180 | K24: =I24-J24 -> 128649 | L24: =L23-K24 -> 47969624
B25: =B24+1 -> 17 | C25: =C24 -> 272270 | D25: =INT(F24*$D$3/12) -> 173682 | E25: =C25-D25 -> 98588 | F25: =F24-E25 -> 48371039 | H25: =H24+1 -> 17 | I25: =I24 -> 216829 | J25: =INT(L24*$J$3/12) -> 87944 | K25: =I25-J25 -> 128885 | L25: =L24-K25 -> 47840739
B26: =B25+1 -> 18 | C26: =C25 -> 272270 | D26: =INT(F25*$D$3/12) -> 173329 | E26: =C26-D26 -> 98941 | F26: =F25-E26 -> 48272098 | H26: =H25+1 -> 18 | I26: =I25 -> 216829 | J26: =INT(L25*$J$3/12) -> 87708 | K26: =I26-J26 -> 129121 | L26: =L25-K26 -> 47711618
B27: =B26+1 -> 19 | C27: =C26 -> 272270 | D27: =INT(F26*$D$3/12) -> 172975 | E27: =C27-D27 -> 99295 | F27: =F26-E27 -> 48172803 | H27: =H26+1 -> 19 | I27: =I26 -> 216829 | J27: =INT(L26*$J$3/12) -> 87471 | K27: =I27-J27 -> 129358 | L27: =L26-K27 -> 47582260
B28: =B27+1 -> 20 | C28: =C27 -> 272270 | D28: =INT(F27*$D$3/12) -> 172619 | E28: =C28-D28 -> 99651 | F28: =F27-E28 -> 48073152 | H28: =H27+1 -> 20 | I28: =I27 -> 216829 | J28: =INT(L27*$J$3/12) -> 87234 | K28: =I28-J28 -> 129595 | L28: =L27-K28 -> 47452665
B29: =B28+1 -> 21 | C29: =C28 -> 272270 | D29: =INT(F28*$D$3/12) -> 172262 | E29: =C29-D29 -> 100008 | F29: =F28-E29 -> 47973144 | H29: =H28+1 -> 21 | I29: =I28 -> 216829 | J29: =INT(L28*$J$3/12) -> 86996 | K29: =I29-J29 -> 129833 | L29: =L28-K29 -> 47322832
B30: =B29+1 -> 22 | C30: =C29 -> 272270 | D30: =INT(F29*$D$3/12) -> 171903 | E30: =C30-D30 -> 100367 | F30: =F29-E30 -> 47872777 | H30: =H29+1 -> 22 | I30: =I29 -> 216829 | J30: =INT(L29*$J$3/12) -> 86758 | K30: =I30-J30 -> 130071 | L30: =L29-K30 -> 47192761
B31: =B30+1 -> 23 | C31: =C30 -> 272270 | D31: =INT(F30*$D$3/12) -> 171544 | E31: =C31-D31 -> 100726 | F31: =F30-E31 -> 47772051 | H31: =H30+1 -> 23 | I31: =I30 -> 216829 | J31: =INT(L30*$J$3/12) -> 86520 | K31: =I31-J31 -> 130309 | L31: =L30-K31 -> 47062452
B32: =B31+1 -> 24 | C32: =C31 -> 272270 | D32: =INT(F31*$D$3/12) -> 171183 | E32: =C32-D32 -> 101087 | F32: =F31-E32 -> 47670964 | H32: =H31+1 -> 24 | I32: =I31 -> 216829 | J32: =INT(L31*$J$3/12) -> 86281 | K32: =I32-J32 -> 130548 | L32: =L31-K32 -> 46931904
A33: ３年 | B33: =B32+1 -> 25 | C33: =C32 -> 272270 | D33: =INT(F32*$D$3/12) -> 170820 | E33: =C33-D33 -> 101450 | F33: =F32-E33 -> 47569514 | H33: =H32+1 -> 25 | I33: =I32 -> 216829 | J33: =INT(L32*$J$3/12) -> 86041 | K33: =I33-J33 -> 130788 | L33: =L32-K33 -> 46801116
B34: =B33+1 -> 26 | C34: =C33 -> 272270 | D34: =INT(F33*$D$3/12) -> 170457 | E34: =C34-D34 -> 101813 | F34: =F33-E34 -> 47467701 | H34: =H33+1 -> 26 | I34: =I33 -> 216829 | J34: =INT(L33*$J$3/12) -> 85802 | K34: =I34-J34 -> 131027 | L34: =L33-K34 -> 46670089
B35: =B34+1 -> 27 | C35: =C34 -> 272270 | D35: =INT(F34*$D$3/12) -> 170092 | E35: =C35-D35 -> 102178 | F35: =F34-E35 -> 47365523 | H35: =H34+1 -> 27 | I35: =I34 -> 216829 | J35: =INT(L34*$J$3/12) -> 85561 | K35: =I35-J35 -> 131268 | L35: =L34-K35 -> 46538821
B36: =B35+1 -> 28 | C36: =C35 -> 272270 | D36: =INT(F35*$D$3/12) -> 169726 | E36: =C36-D36 -> 102544 | F36: =F35-E36 -> 47262979 | H36: =H35+1 -> 28 | I36: =I35 -> 216829 | J36: =INT(L35*$J$3/12) -> 85321 | K36: =I36-J36 -> 131508 | L36: =L35-K36 -> 46407313
B37: =B36+1 -> 29 | C37: =C36 -> 272270 | D37: =INT(F36*$D$3/12) -> 169359 | E37: =C37-D37 -> 102911 | F37: =F36-E37 -> 47160068 | H37: =H36+1 -> 29 | I37: =I36 -> 216829 | J37: =INT(L36*$J$3/12) -> 85080 | K37: =I37-J37 -> 131749 | L37: =L36-K37 -> 46275564
B38: =B37+1 -> 30 | C38: =C37 -> 272270 | D38: =INT(F37*$D$3/12) -> 168990 | E38: =C38-D38 -> 103280 | F38: =F37-E38 -> 47056788 | H38: =H37+1 -> 30 | I38: =I37 -> 216829 | J38: =INT(L37*$J$3/12) -> 84838 | K38: =I38-J38 -> 131991 | L38: =L37-K38 -> 46143573
B39: =B38+1 -> 31 | C39: =C38 -> 272270 | D39: =INT(F38*$D$3/12) -> 168620 | E39: =C39-D39 -> 103650 | F39: =F38-E39 -> 46953138 | H39: =H38+1 -> 31 | I39: =I38 -> 216829 | J39: =INT(L38*$J$3/12) -> 84596 | K39: =I39-J39 -> 132233 | L39: =L38-K39 -> 46011340
B40: =B39+1 -> 32 | C40: =C39 -> 272270 | D40: =INT(F39*$D$3/12) -> 168248 | E40: =C40-D40 -> 104022 | F40: =F39-E40 -> 46849116 | H40: =H39+1 -> 32 | I40: =I39 -> 216829 | J40: =INT(L39*$J$3/12) -> 84354 | K40: =I40-J40 -> 132475 | L40: =L39-K40 -> 45878865
B41: =B40+1 -> 33 | C41: =C40 -> 272270 | D41: =INT(F40*$D$3/12) -> 167875 | E41: =C41-D41 -> 104395 | F41: =F40-E41 -> 46744721 | H41: =H40+1 -> 33 | I41: =I40 -> 216829 | J41: =INT(L40*$J$3/12) -> 84111 | K41: =I41-J41 -> 132718 | L41: =L40-K41 -> 45746147
B42: =B41+1 -> 34 | C42: =C41 -> 272270 | D42: =INT(F41*$D$3/12) -> 167501 | E42: =C42-D42 -> 104769 | F42: =F41-E42 -> 46639952 | H42: =H41+1 -> 34 | I42: =I41 -> 216829 | J42: =INT(L41*$J$3/12) -> 83867 | K42: =I42-J42 -> 132962 | L42: =L41-K42 -> 45613185
...
